Workbook

Sheet Zakah Engine
A1: Zakat (for Gold in SXR) | F1: Silver | J1: Wife Account | K1: Amount | L1: Zakat | N1: AED | O1: Amount | P1: Zakat
A2: Purity | B2: Gram(s) | C2: 1g Price | D2: Total Price | F2: DXB | G2: Kashmir | J2: HDFC | K2: 35000 | L2: =Table18[[#This Row],[Amount]]/40 -> 875 | N2: HSBC | O2: 100000 | P2: =Table20[[#This Row],[Amount]]/40 -> 2500
A3: 18K | B3: =Table11[[#Totals],[18K]]/40 -> 5.975 | C3: ='#'!B5 -> 10913 | D3: =Table15[[#This Row],[Gram(s)]]*Table15[[#This Row],[1g Price]] -> 65205.175 | F3: =Inventory!N20 -> 32.3375 | G3: =Inventory!N21 -> 1881 | J3: Cash | K3: 1000 | L3: =Table18[[#This Row],[Amount]]/40 -> 25 | N3: Darb | O3: 40 | P3: =Table20[[#This Row],[Amount]]/40 -> 1
A4: 21K | B4: =Table11[[#Totals],[21K]]/40 -> 3.85 | J4: Ribah | K4: 4000 | L4: =Table18[[#This Row],[Amount]] -> 4000 | N4: RTA Parking | O4: 117 | P4: =Table20[[#This Row],[Amount]]/40 -> 2.925
A5: 22K | B5: =Table11[[#Totals],[22K]]/40 -> 10.5625 | C5: ='#'!B3 -> 13338 | D5: =Table15[[#This Row],[Gram(s)]]*Table15[[#This Row],[1g Price]] -> 140882.62 | J5: Total | K5: =SUBTOTAL(109,Table18[Amount]) -> 40000 | L5: =SUBTOTAL(109,Table18[Zakat]) -> 4900 | N5: Salik | O5: 184 | P5: =Table20[[#This Row],[Amount]]/40 -> 4.6
A6: 24K | B6: =Table11[[#Totals],[24K]]/40 -> 0 | G6: INR | N6: Security Deposit (Home / DEWA) | O6: 5600 | P6: =Table20[[#This Row],[Amount]]/40 -> 140
A7: Total | B7: =SUBTOTAL(109,Table15[Gram(s)]) -> 20.3875 | D7: =SUBTOTAL(109,Table15[Total Price]) -> 206087.8 | G7: {=Table15[[#Totals],[Total Price]]+Table18[[#Totals],[Zakat]]+Table19[[#Totals],[Zakat]]+Table23[Kashmir]} -> 229763.8 | J7: INR | K7: Amount | L7: Zakat | N7: E& Money | O7: 7231.1 | P7: =Table20[[#This Row],[Amount]]/40 -> 180.7775
J8: IDFC | K8: 10000 | L8: =Table19[[#This Row],[Amount]]/40 -> 250 | N8: Rent paid in advance | O8: 2000 | P8: =Table20[[#This Row],[Amount]]/40 -> 50
A9: Zakat (for Gold in DXB) | G9: In AED | H9: =G7/'#'!D18 -> 9056.5156 | J9: HDFC | K9: 30000 | L9: =Table19[[#This Row],[Amount]]/40 -> 750 | N9: Phone balance | O9: {=Table17[Total]} -> 37.04 | P9: =Table20[[#This Row],[Amount]]/40 -> 0.926
A10: Purity | B10: Gram(s) | C10: 1g Price | D10: Total Price | J10: HDFC NRO | K10: 40000 | L10: =Table19[[#This Row],[Amount]]/40 -> 1000 | N10: RTA Nol | O10: 400 | P10: =Table20[[#This Row],[Amount]]/40 -> 10
A11: 18K | B11: =Table114[[#Totals],[18K]]/40 -> 20 | C11: ='#'!K6 -> 405.97 | D11: =Table16[[#This Row],[Gram(s)]]*Table16[[#This Row],[1g Price]] -> 8119.4 | J11: EPF | K11: 100000 | L11: =Table19[[#This Row],[Amount]]/40 -> 2500 | N11: SAR (Saudi Riyal) | O11: 220 | P11: =Table20[[#This Row],[Amount]]/40 -> 5.5
A12: 21K | B12: =Table114[[#Totals],[21K]]/40 -> 0 | C12: ='#'!K5 -> 473.64 | D12: =Table16[[#This Row],[Gram(s)]]*Table16[[#This Row],[1g Price]] -> 0 | G12: AED | J12: Cash | K12: 2000 | L12: =Table19[[#This Row],[Amount]]/40 -> 50 | N12: Cash | O12: 53354 | P12: =Table20[[#This Row],[Amount]]/40 -> 1333.85
A13: 22K | B13: =Table114[[#Totals],[22K]]/40 -> 1.3 | C13: ='#'!K4 -> 496.19 | D13: =Table16[[#This Row],[Gram(s)]]*Table16[[#This Row],[1g Price]] -> 645.047 | G13: {=Table16[[#Totals],[Total Price]]+Table20[[#Totals],[Zakat]]+Table23[DXB]} -> 13037.376 | J13: Ribah | K13: 12345 | L13: =Table19[[#This Row],[Amount]] -> 12345 | N13: Other rewards | O13: =Table41[[#Totals],[Amount]] -> 440.528 | P13: =Table20[[#This Row],[Amount]]/40 -> 11.0132
A14: 24K | B14: =Table114[[#Totals],[24K]]/40 -> 0 | C14: ='#'!K3 -> 541.3 | D14: =Table16[[#This Row],[Gram(s)]]*Table16[[#This Row],[1g Price]] -> 0 | J14: Total | K14: =SUBTOTAL(109,Table19[Amount]) -> 194345 | L14: =SUBTOTAL(109,Table19[Zakat]) -> 16895 | N14: Total | O14: =SUBTOTAL(109,Table20[Amount]) -> 169623.67 | P14: =SUBTOTAL(109,Table20[Zakat]) -> 4240.5917
A15: Total | B15: =SUBTOTAL(109,Table16[Gram(s)]) -> 21.3 | D15: =SUBTOTAL(109,Table16[Total Price]) -> 8764.447 | G15: In INR | H15: =G13*'#'!D18 -> 330758.23
C19: Ribah Date | D19: 2026-March-22
K20: Ribah Amount | L20: =L13+L4 -> 16345
C21: Person X | D21: 100
C24: Person Y | D24: 3K

Sheet Inventory
A1: # | B1: Item | C1: 18K | D1: 21K | E1: 22K | F1: 24K | G1: Silver | H1: Date | J1: Statistics
A2: 1 | B2: 10 UK pound | E2: 100 | H2: 2018-22 | J2: Gold | K2: Weight | L2: RAW Value | M2: v(INR) | N2: v(AED)
A3: 2 | B3: necklace | E3: 20.2 | H3: 2019 | J3: SXR_18 | K3: =Table11[[#Totals],[18K]] -> 239 | L3: ='#'!B5*Table2[[#This Row],[Weight]] -> 2608207 | M3: =Table2[[#This Row],[RAW Value]] -> 2608207 | N3: =Table2[[#This Row],[RAW Value]]/'#'!D18 -> 102806.74
A4: 3 | C4: 150 | D4: 100 | H4: 2019 | J4: SXR_22 | K4: =Table11[[#Totals],[22K]] -> 422.5 | L4: ='#'!B3*Table2[[#This Row],[Weight]] -> 5635305 | M4: =Table2[[#This Row],[RAW Value]] -> 5635305 | N4: =Table2[[#This Row],[RAW Value]]/'#'!D18 -> 222124.75
A5: 4 | C5: 32 | H5: 2019 | J5: DXB_18 | K5: =Table114[[#Totals],[18K]] -> 800 | L5: ='#'!K6*Table2[[#This Row],[Weight]] -> 324776 | M5: =Table2[[#This Row],[RAW Value]]*'#'!D18 -> 8239567.1 | N5: =Table2[[#This Row],[RAW Value]] -> 324776
A6: 5 | E6: 3 | G6: 30 | H6: 2018 | J6: DXB_21 | K6: =Table114[[#Totals],[21K]] -> 0 | L6: ='#'!K5*Table2[[#This Row],[Weight]] -> 0 | M6: =Table2[[#This Row],[RAW Value]]*'#'!D18 -> 0 | N6: =Table2[[#This Row],[RAW Value]] -> 0
A7: 6 | E7: 54 | H7: 2018 | J7: DXB_22 | K7: =Table114[[#Totals],[22K]] -> 52 | L7: ='#'!K4*Table2[[#This Row],[Weight]] -> 25801.88 | M7: =Table2[[#This Row],[RAW Value]]*'#'!D18 -> 654593.7 | N7: =Table2[[#This Row],[RAW Value]] -> 25801.88
A8: 7 | E8: 34 | H8: 2019 | J8: DXB_24 | K8: =Table114[[#Totals],[24K]] -> 0 | L8: ='#'!K3*Table2[[#This Row],[Weight]] -> 0 | M8: =Table2[[#This Row],[RAW Value]]*'#'!D18 -> 0 | N8: =Table2[[#This Row],[RAW Value]] -> 0
A9: 8 | E9: 21 | H9: 2019 | J9: Sum | K9: =SUBTOTAL(109,Table2[Weight]) -> 1513.5 | M9: =SUBTOTAL(109,Table2[v(INR)]) -> 17137673 | N9: =SUBTOTAL(109,Table2[v(AED)]) -> 675509.37
A10: 9 | E10: 22 | H10: 2019
A11: 10 | E11: 55 | H11: 2019 | J11: Smile Points | K11: Fils | L11: Dhs
A12: 11 | D12: 54 | E12: 66 | H12: 2018 | J12: 176 | K12: =Table1[[#This Row],[Smile Points]]*0.8 -> 140.8 | L12: =(Table1[[#This Row],[Smile Points]]/125) -> 1.408
A13: 12 | C13: 40 | H13: 2019
A14: 13 | C14: 4 | H14: 2019 | J14: SIM 1 | K14: SIM 2 | L14: Total
A15: 14 | E15: 9.8 | H15: 2019 | J15: 25.85 | K15: 11.19 | L15: =SUM(Table17[[#This Row],[SIM 1]:[SIM 2]]) -> 37.04
A16: 15 | C16: 3 | H16: 2019
A17: 16 | C17: 10 | H17: 2019
A18: 17 | E18: 3.2 | H18: 2022 | J18: Silver DXB
A19: 19 | E19: 5 | H19: 2022 | J19: Location | K19: Weight | L19: Zakat wt. | M19: Unit Price | N19: Zakat | O19: Currency
A20: 20 | G20: 300 | H20: 2019 | J20: Dubai | K20: =Table114[[#Totals],[Silver]] -> 100 | L20: =Table13[[#This Row],[Weight]]/40 -> 2.5 | M20: ='#'!N12 -> 12.935 | N20: =Table13[[#This Row],[Zakat wt.]]*Table13[[#This Row],[Unit Price]] -> 32.3375 | O20: AED
A21: 21 | E21: 1.9 | H21: 2023 | J21: Kashmir | K21: =Table11[[#Totals],[Silver]] -> 330 | L21: =Table13[[#This Row],[Weight]]/40 -> 8.25 | M21: ='#'!B12 -> 228 | N21: =Table13[[#This Row],[Zakat wt.]]*Table13[[#This Row],[Unit Price]] -> 1881 | O21: INR
A22: 22 | E22: 15 | H22: 2022
A23: 23 | B23: Bracelet | Mahr | E23: 12.4 | H23: 2018
B24: Totals | C24: =SUBTOTAL(109,Table11[18K]) -> 239 | D24: =SUBTOTAL(109,Table11[21K]) -> 154 | E24: =SUBTOTAL(109,Table11[22K]) -> 422.5 | F24: =SUBTOTAL(109,Table11[24K]) -> 0 | G24: =SUBTOTAL(109,Table11[Silver]) -> 330 | J24: Nisaab | K24: Gold | L24: Silver
J25: # in AED | K25: =85*'#'!K3 -> 46010.5 | L25: =595*'#'!N12 -> 7696.325
A26: # | B26: Item | C26: 18K | D26: 21K | E26: 22K | F26: 24K | G26: Silver | H26: Date | J26: # in INR | K26: =K25*'#'!D18 -> 1167286.4 | L26: =L25*'#'!D18 -> 195255.77
A27: 1 | B27: Silver Quran Reader | G27: 100 | H27: 2019
A28: 2 | B28: Diamond Ring | H28: 2022 | J28: Reward App | K28: Amount
A29: 3 | E29: 52 | H29: 2019 | J29: Shukran | K29: 7.9
A30: 4 | C30: 700 | H30: 2019 | J30: Aura | K30: 9.66
A31: 5 | C31: 100 | H31: 2023 | J31: Amber | K31: 5.69
B32: Totals | C32: =SUBTOTAL(109,Table114[18K]) -> 800 | D32: =SUBTOTAL(109,Table114[21K]) -> 0 | E32: =SUBTOTAL(109,Table114[22K]) -> 52 | F32: =SUBTOTAL(109,Table114[24K]) -> 0 | G32: =SUBTOTAL(109,Table114[Silver]) -> 100 | J32: Yes Rewards | K32: 5.4
J33: Emcan | K33: 1.36
J34: Aster | K34: 0.34
J35: Life | K35: 50
J36: E&-M (Iflah) | K36: 100
J37: E&-M (Aamer) | K37: 0
J38: Smiles | K38: {=Table1[Dhs]} -> 1.408
J39: Temu | K39: 0
J40: Amazon | K40: 200
...

Sheet #
A1: Gold Kashmir | B1: 1 Gram | C1: 10 Gram | D1: 100 Gram | E1: 1 Kilogram | F1: 1 Ounce | G1: 1 Tola | J1: Gold UAE | K1: Column2 | L1: Column3 | M1: Column32 | N1: Column4 | O1: Column5
A2: Gold 24 Karat (Rs ₹) | B2: 14551 | C2: 145510 | D2: 1455100 | E2: 14551000 | F2: 412514 | G2: 169720 | J2: Ounce | K2: 16836 | L2: 16836 | O2: 16836
A3: Gold 22 Karat (Rs ₹) | B3: 13338 | C3: 133384 | D3: 1333842 | E3: 13338417 | F3: 378138 | G3: 155577 | J3: 24K | K3: 541.3 | L3: 541.3 | O3: 541.3
A4: Gold 20 Karat (Rs ₹) | B4: 12126 | C4: 121258 | D4: 1212583 | E4: 12125833 | F4: 343762 | G4: 141433 | J4: 22K | K4: 496.19 | L4: 496.19 | O4: 496.19
A5: Gold 18 Karat (Rs ₹) | B5: 10913 | C5: 109133 | D5: 1091325 | E5: 10913250 | F5: 309385 | G5: 127290 | J5: 21K | K5: 473.64 | L5: 473.64 | O5: 473.64
A6: Gold 16 Karat (Rs ₹) | B6: 9701 | C6: 97007 | D6: 970067 | E6: 9700667 | F6: 275009 | G6: 113147 | J6: 18K | K6: 405.97 | L6: 405.97 | O6: 405.97
A7: Gold 14 Karat (Rs ₹) | B7: 8488 | C7: 84881 | D7: 848808 | E7: 8488083 | F7: 240633 | G7: 99003
A8: Gold 12 Karat (Rs ₹) | B8: 7276 | C8: 72755 | D8: 727550 | E8: 7275500 | F8: 206257 | G8: 84860
A9: Gold 10 Karat (Rs ₹) | B9: 6063 | C9: 60629 | D9: 606292 | E9: 6062917 | F9: 171881 | G9: 70717
A11: SIlver Kashmir | B11: 1 Gram | C11: 10 Gram | D11: 100 Gram | E11: 1 Kilogram | F11: 2 Ounce | G11: 1 Ounce | H11: 1 Tola | J11: Silver UAE | K11: Column2 | L11: Column3 | M11: Column4 | N11: 1g
A12: Silver 999 Fine (Rs ₹) | B12: 228 | C12: 2279 | D12: 22794 | E12: 227940 | G12: 6462 | H12: 2659 | J12: Kilo (AED) | K12: 12935 | L12: 12935 | M12: 13095 | N12: =Silver_UAE[[#This Row],[Column2]]/1000 -> 12.935
A13: Silver 925 Sterling (Rs ₹) | B13: 211 | C13: 2108 | D13: 21084 | E13: 210845 | G13: 5977 | H13: 2459 | J13: Kilo (USD) | K13: 3525 | L13: 3525 | M13: 3568 | N13: =Silver_UAE[[#This Row],[Column2]]/1000 -> 3.525
A14: Silver 900 Coin (Rs ₹) | B14: 205 | C14: 2051 | D14: 20515 | E14: 205146 | G14: 5816 | H14: 2393
A15: Silver 800 German (Rs ₹) | B15: 182 | C15: 1824 | D15: 18235 | E15: 182352 | G15: 5170 | H15: 2127
A17: Currencies | B17: Column2 | C17: Column3 | D17: Column4
A18: Indian Rupee (INR) | B18: 25.37 | C18: 25.37 | D18: 25.37
A19: Pakistani Rupee (PKR) | B19: 76.03 | C19: 76.03 | D19: 76.03
A20: Bangladesh Taka (BDT) | B20: 33.35 | C20: 33.35 | D20: 33.35
A21: Sri Lankan Rupee (LKR) | B21: 84.8 | C21: 84.80 | D21: 84.8
A22: Nepalese Rupee (NPR) | B22: 40.47 | C22: 40.70 | D22: 40.47
A23: Egyptian Pound (EGP) | B23: 14.02 | C23: 14.02 | D23: 14.02
A24: Philippines Peso (PHP) | B24: 16.33 | C24: 16.33 | D24: 16.33
